<?xml version="1.0" encoding="utf-8"?>
<!-- This URDF was automatically created by SolidWorks to URDF Exporter! Originally created by Stephen Brawner (brawner@gmail.com) 
     Commit Version: 1.6.0-4-g7f85cfe  Build Version: 1.6.7995.38578
     For more information, please see http://wiki.ros.org/sw_urdf_exporter -->
<robot
  name="irmv_v2_0319">
  <mujoco>
        <compiler 
        meshdir="../meshes/" 
        balanceinertia="true" 
        discardvisual="false" />
  </mujoco>


  <link
    name="Link_base">
    <inertial>
      <origin
        xyz="-0.015775 -3.32E-05 0.1209"
        rpy="0 0 0" />
      <mass
        value="1.7973" />
      <inertia
        ixx="0.017873"
        ixy="-1.18E-06"
        ixz="-9.241E-05"
        iyy="0.0011627"
        iyz="-4.3E-07"
        izz="0.017859" />
    </inertial>
    <visual>
      <origin
        xyz="0 0 0"
        rpy="0 0 0" />
      <geometry>
        <mesh
          filename="../meshes/Link_base.STL" />
      </geometry>
      <material
        name="">
        <color
          rgba="0.75294 0.75294 0.75294 1" />
      </material>
    </visual>
    <collision>
      <origin
        xyz="0 0 0"
        rpy="0 0 0" />
      <geometry>
        <mesh
          filename="../meshes/Link_base.STL" />
      </geometry>
    </collision>
  </link>

<link
    name="Link_body">
    <inertial>
      <origin
        xyz="-0.017923 0.0012904 0.22071"
        rpy="0 0 0" />
      <mass
        value="4.93" />
      <inertia
        ixx="0.071345"
        ixy="0.0005038"
        ixz="-0.0050769"
        iyy="0.035788"
        iyz="6.077E-05"
        izz="0.061634" />
    </inertial>
    <visual>
      <origin
        xyz="0 0 0"
        rpy="0 0 0" />
      <geometry>
        <mesh
          filename="../meshes/Link_body.STL" />
      </geometry>
      <material
        name="">
        <color
          rgba="0.75294 0.75294 0.75294 1" />
      </material>
    </visual>
    <collision>
      <origin
        xyz="0 0 0"
        rpy="0 0 0" />
      <geometry>
        <mesh
          filename="../meshes/Link_body.STL" />
      </geometry>
    </collision>
  </link>

  <joint
    name="Joint_body"
    type="fixed">
    <origin
      xyz="0 0 0"
      rpy="0 0 0" />
    <parent
      link="Link_base" />
    <child
      link="Link_body" />
    <axis
      xyz="0 0 1" />
  </joint>

  <link
    name="Link_hip_l_yaw">
    <inertial>
      <origin
        xyz="0.0021922 -4.922E-05 0.0025535"
        rpy="0 0 0" />
      <mass
        value="0.9411" />
      <inertia
        ixx="0.00073271"
        ixy="-1.13E-06"
        ixz="9.736E-05"
        iyy="0.00068327"
        iyz="7.2E-07"
        izz="0.00076393" />
    </inertial>
    <visual>
      <origin
        xyz="0 0 0"
        rpy="0 0 0" />
      <geometry>
        <mesh
          filename="../meshes/Link_hip_l_yaw.STL" />
      </geometry>
      <material
        name="">
        <color
          rgba="0.75294 0.75294 0.75294 1" />
      </material>
    </visual>
    <collision>
      <origin
        xyz="0 0 0"
        rpy="0 0 0" />
      <geometry>
        <mesh
          filename="../meshes/Link_hip_l_yaw.STL" />
      </geometry>
    </collision>
  </link>
  <joint
    name="Joint_hip_l_yaw"
    type="revolute">
    <origin
      xyz="-0.068236 0.1 0.068236"
      rpy="0 0 0" />
    <parent
      link="Link_base" />
    <child
      link="Link_hip_l_yaw" />
    <axis
      xyz="0.70711 0 0.70711" />
    <limit
      lower="-1.5708"
      upper="1.5708"
      effort="40"
      velocity="3.45 " />
  </joint>
  <link
    name="Link_hip_l_roll">
    <inertial>
      <origin
        xyz="-0.0033731 0.036973 0.0032853"
        rpy="0 0 0" />
      <mass
        value="1.7075" />
      <inertia
        ixx="0.0020338"
        ixy="0.00015887"
        ixz="-0.00012869"
        iyy="0.0031046"
        iyz="-0.00016472"
        izz="0.0020345" />
    </inertial>
    <visual>
      <origin
        xyz="0 0 0"
        rpy="0 0 0" />
      <geometry>
        <mesh
          filename="../meshes/Link_hip_l_roll.STL" />
      </geometry>
      <material
        name="">
        <color
          rgba="0.75294 0.75294 0.75294 1" />
      </material>
    </visual>
    <collision>
      <origin
        xyz="0 0 0"
        rpy="0 0 0" />
      <geometry>
        <mesh
          filename="../meshes/Link_hip_l_roll.STL" />
      </geometry>
    </collision>
  </link>
  <joint
    name="Joint_hip_l_roll"
    type="revolute">
    <origin
      xyz="0.068236 0 -0.068236"
      rpy="0 0 0" />
    <parent
      link="Link_hip_l_yaw" />
    <child
      link="Link_hip_l_roll" />
    <axis
      xyz="0.70711 0 -0.70711" />
    <limit
      lower="-1.5708"
      upper="1.5708"
      effort="40"
      velocity="3.45" />
  </joint>
  <link
    name="Link_hip_l_pitch">
    <inertial>
      <origin
        xyz="0.0011796 -0.016905 -0.026609"
        rpy="0 0 0" />
      <mass
        value="1.9602" />
      <inertia
        ixx="0.0087865"
        ixy="3.373E-05"
        ixz="-0.00012703"
        iyy="0.0095896"
        iyz="-0.00088229"
        izz="0.0018987" />
    </inertial>
    <visual>
      <origin
        xyz="0 0 0"
        rpy="0 0 0" />
      <geometry>
        <mesh
          filename="../meshes/Link_hip_l_pitch.STL" />
      </geometry>
      <material
        name="">
        <color
          rgba="0.75294 0.75294 0.75294 1" />
      </material>
    </visual>
    <collision>
      <origin
        xyz="0 0 0"
        rpy="0 0 0" />
      <geometry>
        <mesh
          filename="../meshes/Link_hip_l_pitch.STL" />
      </geometry>
    </collision>
  </link>
  <joint
    name="Joint_hip_l_pitch"
    type="revolute">
    <origin
      xyz="0 0 0"
      rpy="0 0 0" />
    <parent
      link="Link_hip_l_roll" />
    <child
      link="Link_hip_l_pitch" />
    <axis
      xyz="0 -1 0" />
    <limit
      lower="-0.9948"
      upper="2.2689"
      effort="45"
      velocity="15.71" />
  </joint>
  <link
    name="Link_knee_l_pitch">
    <inertial>
      <origin
        xyz="-0.0066852 0.00034298 -0.093038"
        rpy="0 0 0" />
      <mass
        value="1.0785" />
      <inertia
        ixx="0.002539"
        ixy="1.046E-05"
        ixz="-6.296E-05"
        iyy="0.0025304"
        iyz="-3.58E-06"
        izz="0.00051393" />
    </inertial>
    <visual>
      <origin
        xyz="0 0 0"
        rpy="0 0 0" />
      <geometry>
        <mesh
          filename="../meshes/Link_knee_l_pitch.STL" />
      </geometry>
      <material
        name="">
        <color
          rgba="0.75294 0.75294 0.75294 1" />
      </material>
    </visual>
    <collision>
      <origin
        xyz="0 0 0"
        rpy="0 0 0" />
      <geometry>
        <mesh
          filename="../meshes/Link_knee_l_pitch.STL" />
      </geometry>
    </collision>
  </link>
  <joint
    name="Joint_knee_l_pitch"
    type="revolute">
    <origin
      xyz="0 0 -0.2"
      rpy="0 0 0" />
    <parent
      link="Link_hip_l_pitch" />
    <child
      link="Link_knee_l_pitch" />
    <axis
      xyz="0 -1 0" />
    <limit
      lower="-2.0944"
      upper="0"
      effort="45"
      velocity="15.71" />
  </joint>
  <link
    name="Link_ankle_l_pitch">
    <inertial>
      <origin
        xyz="0 -0.00061416 -0.010352"
        rpy="0 0 0" />
      <mass
        value="0.058811" />
      <inertia
        ixx="9.9632E-06"
        ixy="-1.0683E-20"
        ixz="2.5225E-21"
        iyy="1.6724E-05"
        iyz="4.3857E-20"
        izz="1.0652E-05" />
    </inertial>
    <visual>
      <origin
        xyz="0 0 0"
        rpy="0 0 0" />
      <geometry>
        <mesh
          filename="../meshes/Link_ankle_l_pitch.STL" />
      </geometry>
      <material
        name="">
        <color
          rgba="0.75294 0.75294 0.75294 1" />
      </material>
    </visual>
    <collision>
      <origin
        xyz="0 0 0"
        rpy="0 0 0" />
      <geometry>
        <mesh
          filename="../meshes/Link_ankle_l_pitch.STL" />
      </geometry>
    </collision>
  </link>
  <joint
    name="Joint_ankle_l_pitch"
    type="revolute">
    <origin
      xyz="0 0 -0.2"
      rpy="0 0 0" />
    <parent
      link="Link_knee_l_pitch" />
    <child
      link="Link_ankle_l_pitch" />
    <axis
      xyz="0 -1 0" />
    <limit
      lower="-0.6632"
      upper="0.3491"
      effort="36"
      velocity="7.54" />
  </joint>
  <link
    name="Link_ankle_l_roll">
    <inertial>
      <origin
        xyz="0.021459 0 -0.01976"
        rpy="0 0 0" />
      <mass
        value="0.22291" />
      <inertia
        ixx="6.837E-05"
        ixy="-1.6692E-05"
        ixz="4.4053E-06"
        iyy="0.00031616"
        iyz="4.5799E-07"
        izz="0.00032322" />
    </inertial>
    <visual>
      <origin
        xyz="0 0 0"
        rpy="0 0 0" />
      <geometry>
        <mesh
          filename="../meshes/Link_ankle_l_roll.STL" />
      </geometry>
      <material
        name="">
        <color
          rgba="0.75294 0.75294 0.75294 1" />
      </material>
    </visual>
    <collision>
      <origin
        xyz="0.05 0 -0.008"
        rpy="0 0 0" />
      <geometry>
        <!-- <mesh
          filename="../meshes/Link_ankle_l_roll.STL" /> -->
        <box size="0.20 0.05 0.05" />
      </geometry>
    </collision>
  </link>
  <joint
    name="Joint_ankle_l_roll"
    type="fixed">
    <origin
      xyz="0 0 -0.018"
      rpy="0 0 0" />
    <parent
      link="Link_ankle_l_pitch" />
    <child
      link="Link_ankle_l_roll" />
    <axis
      xyz="1 0 0" />
  </joint>
  <link
    name="Link_hip_r_yaw">
    <inertial>
      <origin
        xyz="0.0021922 4.922E-05 0.0025535"
        rpy="0 0 0" />
      <mass
        value="0.9411" />
      <inertia
        ixx="0.00073271"
        ixy="1.13E-06"
        ixz="9.736E-05"
        iyy="0.00068327"
        iyz="-7.2E-07"
        izz="0.00076393" />
    </inertial>
    <visual>
      <origin
        xyz="0 0 0"
        rpy="0 0 0" />
      <geometry>
        <mesh
          filename="../meshes/Link_hip_r_yaw.STL" />
      </geometry>
      <material
        name="">
        <color
          rgba="0.75294 0.75294 0.75294 1" />
      </material>
    </visual>
    <collision>
      <origin
        xyz="0 0 0"
        rpy="0 0 0" />
      <geometry>
        <mesh
          filename="../meshes/Link_hip_r_yaw.STL" />
      </geometry>
    </collision>
  </link>
  <joint
    name="Joint_hip_r_yaw"
    type="revolute">
    <origin
      xyz="-0.068236 -0.1 0.068236"
      rpy="0 0 0" />
    <parent
      link="Link_base" />
    <child
      link="Link_hip_r_yaw" />
    <axis
      xyz="0.70711 0 0.70711" />
    <limit
      lower="-1.5708"
      upper="1.5708"
      effort="40"
      velocity="3.45" />
  </joint>
  <link
    name="Link_hip_r_roll">
    <inertial>
      <origin
        xyz="-0.0033731 -0.036973 0.0032853"
        rpy="0 0 0" />
      <mass
        value="1.7075" />
      <inertia
        ixx="0.0020338"
        ixy="-0.00015887"
        ixz="-0.00012869"
        iyy="0.0031046"
        iyz="0.00016472"
        izz="0.0020345" />
    </inertial>
    <visual>
      <origin
        xyz="0 0 0"
        rpy="0 0 0" />
      <geometry>
        <mesh
          filename="../meshes/Link_hip_r_roll.STL" />
      </geometry>
      <material
        name="">
        <color
          rgba="0.75294 0.75294 0.75294 1" />
      </material>
    </visual>
    <collision>
      <origin
        xyz="0 0 0"
        rpy="0 0 0" />
      <geometry>
        <mesh
          filename="../meshes/Link_hip_r_roll.STL" />
      </geometry>
    </collision>
  </link>
  <joint
    name="Joint_hip_r_roll"
    type="revolute">
    <origin
      xyz="0.068236 0 -0.068236"
      rpy="0 0 0" />
    <parent
      link="Link_hip_r_yaw" />
    <child
      link="Link_hip_r_roll" />
    <axis
      xyz="0.70711 0 -0.70711" />
    <limit
      lower="-1.5708"
      upper="1.5708"
      effort="40"
      velocity="3.45" />
  </joint>
  <link
    name="Link_hip_r_pitch">
    <inertial>
      <origin
        xyz="0.00117955 0.01690499 -0.02660882"
        rpy="0 0 0" />
      <mass
        value="1.9602" />
      <inertia
        ixx="0.0087865"
        ixy="-3.373E-05"
        ixz="-0.00012703"
        iyy="0.0095896"
        iyz="0.00088229"
        izz="0.0018987" />
    </inertial>
    <visual>
      <origin
        xyz="0 0 0"
        rpy="0 0 0" />
      <geometry>
        <mesh
          filename="../meshes/Link_hip_r_pitch.STL" />
      </geometry>
      <material
        name="">
        <color
          rgba="0.75294 0.75294 0.75294 1" />
      </material>
    </visual>
    <collision>
      <origin
        xyz="0 0 0"
        rpy="0 0 0" />
      <geometry>
        <mesh
          filename="../meshes/Link_hip_r_pitch.STL" />
      </geometry>
    </collision>
  </link>
  <joint
    name="Joint_hip_r_pitch"
    type="revolute">
    <origin
      xyz="0 0 0"
      rpy="0 0 0" />
    <parent
      link="Link_hip_r_roll" />
    <child
      link="Link_hip_r_pitch" />
    <axis
      xyz="0 -1 0" />
    <limit
      lower="-0.9948"
      upper="2.2689"
      effort="45"
      velocity="15.71" />
  </joint>
  <link
    name="Link_knee_r_pitch">
    <inertial>
      <origin
        xyz="-0.0066852 -0.00034298 -0.093038"
        rpy="0 0 0" />
      <mass
        value="1.0785" />
      <inertia
        ixx="0.002539"
        ixy="-1.046E-05"
        ixz="-6.296E-05"
        iyy="0.0025304"
        iyz="3.58E-06"
        izz="0.00051393" />
    </inertial>
    <visual>
      <origin
        xyz="0 0 0"
        rpy="0 0 0" />
      <geometry>
        <mesh
          filename="../meshes/Link_knee_r_pitch.STL" />
      </geometry>
      <material
        name="">
        <color
          rgba="0.75294 0.75294 0.75294 1" />
      </material>
    </visual>
    <collision>
      <origin
        xyz="0 0 0"
        rpy="0 0 0" />
      <geometry>
        <mesh
          filename="../meshes/Link_knee_r_pitch.STL" />
      </geometry>
    </collision>
  </link>
  <joint
    name="Joint_knee_r_pitch"
    type="revolute">
    <origin
      xyz="0 0 -0.2"
      rpy="0 0 0" />
    <parent
      link="Link_hip_r_pitch" />
    <child
      link="Link_knee_r_pitch" />
    <axis
      xyz="0 -1 0" />
    <limit
      lower="-2.0944"
      upper="0"
      effort="45"
      velocity="15.71" />
  </joint>
  <link
    name="Link_ankle_r_pitch">
    <inertial>
      <origin
        xyz="0 0.00061416 -0.010352"
        rpy="0 0 0" />
      <mass
        value="0.058811" />
      <inertia
        ixx="9.9632E-06"
        ixy="5.6296E-20"
        ixz="-2.5023E-21"
        iyy="1.6724E-05"
        iyz="-3.9436E-20"
        izz="1.0652E-05" />
    </inertial>
    <visual>
      <origin
        xyz="0 0 0"
        rpy="0 0 0" />
      <geometry>
        <mesh
          filename="../meshes/Link_ankle_r_pitch.STL" />
      </geometry>
      <material
        name="">
        <color
          rgba="0.75294 0.75294 0.75294 1" />
      </material>
    </visual>
    <collision>
      <origin
        xyz="0 0 0"
        rpy="0 0 0" />
      <geometry>
        <mesh
          filename="../meshes/Link_ankle_r_pitch.STL" />
      </geometry>
    </collision>
  </link>
  <joint
    name="Joint_ankle_r_pitch"
    type="revolute">
    <origin
      xyz="0 0 -0.2"
      rpy="0 0 0" />
    <parent
      link="Link_knee_r_pitch" />
    <child
      link="Link_ankle_r_pitch" />
    <axis
      xyz="0 -1 0" />
    <limit
      lower="-0.6632"
      upper="0.3491"
      effort="36"
      velocity="7.54" />
  </joint>
  <link
    name="Link_ankle_r_roll">
    <inertial>
      <origin
        xyz="0.0214588 0 -0.01975951"
        rpy="0 0 0" />
      <mass
        value="0.22291" />
      <inertia
        ixx="6.837E-05"
        ixy="1.6693E-05"
        ixz="4.4053E-06"
        iyy="0.00031616"
        iyz="-4.5795E-07"
        izz="0.00032322" />
    </inertial>
    <visual>
      <origin
        xyz="0 0 0"
        rpy="0 0 0" />
      <geometry>
        <mesh
          filename="../meshes/Link_ankle_r_roll.STL" />
      </geometry>
      <material
        name="">
        <color
          rgba="0.75294 0.75294 0.75294 1" />
      </material>
    </visual>
    <collision>
      <origin
        xyz="0.05 0 -0.008"
        rpy="0 0 0" />
      <geometry>
        <!-- <mesh
          filename="../meshes/Link_ankle_r_roll.STL" /> -->
        <box size="0.20 0.05 0.05" />
      </geometry>
    </collision>
  </link>
  <joint
    name="Joint_ankle_r_roll"
    type="fixed">
    <origin
      xyz="0 0 -0.018"
      rpy="0 0 0" />
    <parent
      link="Link_ankle_r_pitch" />
    <child
      link="Link_ankle_r_roll" />
    <axis
      xyz="1 0 0" />
  </joint>
</robot>